Workbook

Sheet Matrix
A1: Equoria: Temperament Effects by Competition
A2: Green = Positive · Red = Negative · Gray = Neutral. Edit any cell to Positive / Negative / Neutral; count columns update automatically.
A4: Competition | B4: Spirited | C4: Nervous | D4: Calm | E4: Bold | F4: Steady | G4: Independent | H4: Reactive | I4: Stubborn | J4: Playful | K4: Lazy | L4: Aggressive | M4: # Positive | N4: # Negative | O4: # Neutral
A5: Western Pleasure | B5: Neutral | C5: Negative | D5: Positive | E5: Neutral | F5: Positive | G5: Negative | H5: Negative | I5: Negative | J5: Neutral | K5: Positive | L5: Negative | M5: =COUNTIF($B5:$L5,"Positive") -> 3 | N5: =COUNTIF($B5:$L5,"Negative") -> 5 | O5: =COUNTIF($B5:$L5,"Neutral") -> 3
A6: Reining | B6: Positive | C6: Negative | D6: Neutral | E6: Positive | F6: Positive | G6: Neutral | H6: Neutral | I6: Negative | J6: Negative | K6: Negative | L6: Negative | M6: =COUNTIF($B6:$L6,"Positive") -> 3 | N6: =COUNTIF($B6:$L6,"Negative") -> 5 | O6: =COUNTIF($B6:$L6,"Neutral") -> 3
A7: Cutting | B7: Positive | C7: Negative | D7: Positive | E7: Positive | F7: Neutral | G7: Positive | H7: Positive | I7: Negative | J7: Neutral | K7: Negative | L7: Neutral | M7: =COUNTIF($B7:$L7,"Positive") -> 5 | N7: =COUNTIF($B7:$L7,"Negative") -> 3 | O7: =COUNTIF($B7:$L7,"Neutral") -> 3
A8: Barrel Racing | B8: Positive | C8: Negative | D8: Neutral | E8: Positive | F8: Neutral | G8: Neutral | H8: Neutral | I8: Negative | J8: Neutral | K8: Negative | L8: Negative | M8: =COUNTIF($B8:$L8,"Positive") -> 2 | N8: =COUNTIF($B8:$L8,"Negative") -> 4 | O8: =COUNTIF($B8:$L8,"Neutral") -> 5
A9: Roping | B9: Neutral | C9: Negative | D9: Positive | E9: Positive | F9: Positive | G9: Positive | H9: Neutral | I9: Negative | J9: Negative | K9: Negative | L9: Negative | M9: =COUNTIF($B9:$L9,"Positive") -> 4 | N9: =COUNTIF($B9:$L9,"Negative") -> 5 | O9: =COUNTIF($B9:$L9,"Neutral") -> 2
A10: Team Penning | B10: Positive | C10: Negative | D10: Neutral | E10: Positive | F10: Neutral | G10: Positive | H10: Neutral | I10: Negative | J10: Neutral | K10: Negative | L10: Negative | M10: =COUNTIF($B10:$L10,"Positive") -> 3 | N10: =COUNTIF($B10:$L10,"Negative") -> 4 | O10: =COUNTIF($B10:$L10,"Neutral") -> 4
A11: Rodeo | B11: Positive | C11: Negative | D11: Neutral | E11: Positive | F11: Positive | G11: Neutral | H11: Negative | I11: Negative | J11: Neutral | K11: Negative | L11: Negative | M11: =COUNTIF($B11:$L11,"Positive") -> 3 | N11: =COUNTIF($B11:$L11,"Negative") -> 5 | O11: =COUNTIF($B11:$L11,"Neutral") -> 3
A12: Hunter | B12: Negative | C12: Negative | D12: Positive | E12: Neutral | F12: Positive | G12: Neutral | H12: Negative | I12: Negative | J12: Neutral | K12: Neutral | L12: Negative | M12: =COUNTIF($B12:$L12,"Positive") -> 2 | N12: =COUNTIF($B12:$L12,"Negative") -> 5 | O12: =COUNTIF($B12:$L12,"Neutral") -> 4
A13: Saddleseat | B13: Positive | C13: Negative | D13: Neutral | E13: Positive | F13: Neutral | G13: Negative | H13: Neutral | I13: Negative | J13: Neutral | K13: Negative | L13: Negative | M13: =COUNTIF($B13:$L13,"Positive") -> 2 | N13: =COUNTIF($B13:$L13,"Negative") -> 5 | O13: =COUNTIF($B13:$L13,"Neutral") -> 4
A14: Endurance | B14: Neutral | C14: Negative | D14: Positive | E14: Positive | F14: Positive | G14: Positive | H14: Negative | I14: Negative | J14: Neutral | K14: Negative | L14: Negative | M14: =COUNTIF($B14:$L14,"Positive") -> 4 | N14: =COUNTIF($B14:$L14,"Negative") -> 5 | O14: =COUNTIF($B14:$L14,"Neutral") -> 2
A15: Eventing | B15: Positive | C15: Negative | D15: Positive | E15: Positive | F15: Neutral | G15: Positive | H15: Negative | I15: Negative | J15: Neutral | K15: Negative | L15: Negative | M15: =COUNTIF($B15:$L15,"Positive") -> 4 | N15: =COUNTIF($B15:$L15,"Negative") -> 5 | O15: =COUNTIF($B15:$L15,"Neutral") -> 2
A16: Dressage | B16: Neutral | C16: Negative | D16: Positive | E16: Neutral | F16: Positive | G16: Negative | H16: Negative | I16: Negative | J16: Neutral | K16: Neutral | L16: Negative | M16: =COUNTIF($B16:$L16,"Positive") -> 2 | N16: =COUNTIF($B16:$L16,"Negative") -> 5 | O16: =COUNTIF($B16:$L16,"Neutral") -> 4
... A27: Racing | B27: Positive | C27: Negative | D27: Neutral | E27: Positive | F27: Neutral | G27: Neutral | H27: Neutral | I27: Negative | J27: Neutral | K27: Negative | L27: Neutral | M27: =COUNTIF($B27:$L27,"Positive") -> 2 | N27: =COUNTIF($B27:$L27,"Negative") -> 3 | O27: =COUNTIF($B27:$L27,"Neutral") -> 6
A29: # Positive | B29: =COUNTIF(B$5:B$27,"Positive") -> 16 | C29: =COUNTIF(C$5:C$27,"Positive") -> 0 | D29: =COUNTIF(D$5:D$27,"Positive") -> 11 | E29: =COUNTIF(E$5:E$27,"Positive") -> 17 | F29: =COUNTIF(F$5:F$27,"Positive") -> 10 | G29: =COUNTIF(G$5:G$27,"Positive") -> 8 | H29: =COUNTIF(H$5:H$27,"Positive") -> 1 | I29: =COUNTIF(I$5:I$27,"Positive") -> 0 | ... L29: =COUNTIF(L$5:L$27,"Positive") -> 0
A30: # Negative | B30: =COUNTIF(B$5:B$27,"Negative") -> 2 | C30: =COUNTIF(C$5:C$27,"Negative") -> 23 | D30: =COUNTIF(D$5:D$27,"Negative") -> 0 | E30: =COUNTIF(E$5:E$27,"Negative") -> 0 | F30: =COUNTIF(F$5:F$27,"Negative") -> 0 | G30: =COUNTIF(G$5:G$27,"Negative") -> 5 | H30: =COUNTIF(H$5:H$27,"Negative") -> 13 | I30: =COUNTIF(I$5:I$27,"Negative") -> 23 | ... L30: =COUNTIF(L$5:L$27,"Negative") -> 18
A31: # Neutral | B31: =COUNTIF(B$5:B$27,"Neutral") -> 5 | C31: =COUNTIF(C$5:C$27,"Neutral") -> 0 | D31: =COUNTIF(D$5:D$27,"Neutral") -> 12 | E31: =COUNTIF(E$5:E$27,"Neutral") -> 6 | F31: =COUNTIF(F$5:F$27,"Neutral") -> 13 | G31: =COUNTIF(G$5:G$27,"Neutral") -> 10 | H31: =COUNTIF(H$5:H$27,"Neutral") -> 9 | I31: =COUNTIF(I$5:I$27,"Neutral") -> 0 | ... L31: =COUNTIF(L$5:L$27,"Neutral") -> 5

Sheet Long Format
A1: Competition | B1: Temperament | C1: Effect | D1: Modifier
A2: Western Pleasure | B2: Spirited | C2: =Matrix!B5 -> Neutral | D2: =IF(C2="Positive",1,IF(C2="Negative",-1,0)) -> 0
A3: Western Pleasure | B3: Nervous | C3: =Matrix!C5 -> Negative | D3: =IF(C3="Positive",1,IF(C3="Negative",-1,0)) -> -1
A4: Western Pleasure | B4: Calm | C4: =Matrix!D5 -> Positive | D4: =IF(C4="Positive",1,IF(C4="Negative",-1,0)) -> 1
A5: Western Pleasure | B5: Bold | C5: =Matrix!E5 -> Neutral | D5: =IF(C5="Positive",1,IF(C5="Negative",-1,0)) -> 0
A6: Western Pleasure | B6: Steady | C6: =Matrix!F5 -> Positive | D6: =IF(C6="Positive",1,IF(C6="Negative",-1,0)) -> 1
A7: Western Pleasure | B7: Independent | C7: =Matrix!G5 -> Negative | D7: =IF(C7="Positive",1,IF(C7="Negative",-1,0)) -> -1
A8: Western Pleasure | B8: Reactive | C8: =Matrix!H5 -> Negative | D8: =IF(C8="Positive",1,IF(C8="Negative",-1,0)) -> -1
A9: Western Pleasure | B9: Stubborn | C9: =Matrix!I5 -> Negative | D9: =IF(C9="Positive",1,IF(C9="Negative",-1,0)) -> -1
A10: Western Pleasure | B10: Playful | C10: =Matrix!J5 -> Neutral | D10: =IF(C10="Positive",1,IF(C10="Negative",-1,0)) -> 0
A11: Western Pleasure | B11: Lazy | C11: =Matrix!K5 -> Positive | D11: =IF(C11="Positive",1,IF(C11="Negative",-1,0)) -> 1
A12: Western Pleasure | B12: Aggressive | C12: =Matrix!L5 -> Negative | D12: =IF(C12="Positive",1,IF(C12="Negative",-1,0)) -> -1
A13: Reining | B13: Spirited | C13: =Matrix!B6 -> Positive | D13: =IF(C13="Positive",1,IF(C13="Negative",-1,0)) -> 1
A14: Reining | B14: Nervous | C14: =Matrix!C6 -> Negative | D14: =IF(C14="Positive",1,IF(C14="Negative",-1,0)) -> -1
A15: Reining | B15: Calm | C15: =Matrix!D6 -> Neutral | D15: =IF(C15="Positive",1,IF(C15="Negative",-1,0)) -> 0
A16: Reining | B16: Bold | C16: =Matrix!E6 -> Positive | D16: =IF(C16="Positive",1,IF(C16="Negative",-1,0)) -> 1
A17: Reining | B17: Steady | C17: =Matrix!F6 -> Positive | D17: =IF(C17="Positive",1,IF(C17="Negative",-1,0)) -> 1
A18: Reining | B18: Independent | C18: =Matrix!G6 -> Neutral | D18: =IF(C18="Positive",1,IF(C18="Negative",-1,0)) -> 0
A19: Reining | B19: Reactive | C19: =Matrix!H6 -> Neutral | D19: =IF(C19="Positive",1,IF(C19="Negative",-1,0)) -> 0
A20: Reining | B20: Stubborn | C20: =Matrix!I6 -> Negative | D20: =IF(C20="Positive",1,IF(C20="Negative",-1,0)) -> -1
A21: Reining | B21: Playful | C21: =Matrix!J6 -> Negative | D21: =IF(C21="Positive",1,IF(C21="Negative",-1,0)) -> -1
A22: Reining | B22: Lazy | C22: =Matrix!K6 -> Negative | D22: =IF(C22="Positive",1,IF(C22="Negative",-1,0)) -> -1
A23: Reining | B23: Aggressive | C23: =Matrix!L6 -> Negative | D23: =IF(C23="Positive",1,IF(C23="Negative",-1,0)) -> -1
A24: Cutting | B24: Spirited | C24: =Matrix!B7 -> Positive | D24: =IF(C24="Positive",1,IF(C24="Negative",-1,0)) -> 1
A25: Cutting | B25: Nervous | C25: =Matrix!C7 -> Negative | D25: =IF(C25="Positive",1,IF(C25="Negative",-1,0)) -> -1
A26: Cutting | B26: Calm | C26: =Matrix!D7 -> Positive | D26: =IF(C26="Positive",1,IF(C26="Negative",-1,0)) -> 1
A27: Cutting | B27: Bold | C27: =Matrix!E7 -> Positive | D27: =IF(C27="Positive",1,IF(C27="Negative",-1,0)) -> 1
A28: Cutting | B28: Steady | C28: =Matrix!F7 -> Neutral | D28: =IF(C28="Positive",1,IF(C28="Negative",-1,0)) -> 0
A29: Cutting | B29: Independent | C29: =Matrix!G7 -> Positive | D29: =IF(C29="Positive",1,IF(C29="Negative",-1,0)) -> 1
A30: Cutting | B30: Reactive | C30: =Matrix!H7 -> Positive | D30: =IF(C30="Positive",1,IF(C30="Negative",-1,0)) -> 1
A31: Cutting | B31: Stubborn | C31: =Matrix!I7 -> Negative | D31: =IF(C31="Positive",1,IF(C31="Negative",-1,0)) -> -1
A32: Cutting | B32: Playful | C32: =Matrix!J7 -> Neutral | D32: =IF(C32="Positive",1,IF(C32="Negative",-1,0)) -> 0
A33: Cutting | B33: Lazy | C33: =Matrix!K7 -> Negative | D33: =IF(C33="Positive",1,IF(C33="Negative",-1,0)) -> -1
A34: Cutting | B34: Aggressive | C34: =Matrix!L7 -> Neutral | D34: =IF(C34="Positive",1,IF(C34="Negative",-1,0)) -> 0
A35: Barrel Racing | B35: Spirited | C35: =Matrix!B8 -> Positive | D35: =IF(C35="Positive",1,IF(C35="Negative",-1,0)) -> 1
A36: Barrel Racing | B36: Nervous | C36: =Matrix!C8 -> Negative | D36: =IF(C36="Positive",1,IF(C36="Negative",-1,0)) -> -1
A37: Barrel Racing | B37: Calm | C37: =Matrix!D8 -> Neutral | D37: =IF(C37="Positive",1,IF(C37="Negative",-1,0)) -> 0
A38: Barrel Racing | B38: Bold | C38: =Matrix!E8 -> Positive | D38: =IF(C38="Positive",1,IF(C38="Negative",-1,0)) -> 1
A39: Barrel Racing | B39: Steady | C39: =Matrix!F8 -> Neutral | D39: =IF(C39="Positive",1,IF(C39="Negative",-1,0)) -> 0
A40: Barrel Racing | B40: Independent | C40: =Matrix!G8 -> Neutral | D40: =IF(C40="Positive",1,IF(C40="Negative",-1,0)) -> 0
...

Sheet Notes
A1: Competition(s) | B1: Reasoning
A2: Western Pleasure | B2: Lazy = Positive: a slow, low-energy jog and lope is what's judged.
A3: Cutting | B3: Independent = Positive (works the cow on a loose rein); Reactive = Positive (instant response to the cow); Aggressive = Neutral (intimidating cattle helps, aggression toward people/horses doesn't).
A4: Reining / Dressage / Combined Driving / Fine Harness / Saddleseat | B4: Independent = Negative: anticipating or overriding cues is penalized.
A5: Saddleseat / Fine Harness | B5: Spirited and Bold = Positive (judged on animation, brilliance, presence); Calm = Neutral (too quiet looks flat).
A6: Endurance / Eventing / Cross Country / Steeplechase / Polo / Roping | B6: Independent = Positive: the horse must self-rate and read terrain, fences, cattle or the ball.
A7: Show Jumping | B7: Nervous = Neutral: anxious horses are often the most careful about rails.
A8: Racing / Harness Racing / Steeplechase / Polo | B8: Aggressive = Neutral: competitive drive helps, but gate and barn problems cancel it out.
A9: Harness Racing | B9: Steady = Positive, Playful = Negative: breaking stride is penalized.
A10: Gymkhana | B10: Playful = Positive (game-loving ponies thrive); Calm = Positive (tolerates flags and mounting/dismounting at speed).
A11: Rodeo | B11: Treated as all-around rodeo/ranch performance, not bucking stock. For bucking stock, Spirited, Aggressive and Stubborn would lean Positive.
A12: General | B12: Nervous, Stubborn and Aggressive are negative almost everywhere, which matches real life. Adjust these if every temperament should have a niche.
A13: Spelling | B13: The sport is spelled 'Reining' (not 'Reigning').
